Workbook

Sheet Cover
B2: PT. PRIMAVISTA SOLUSI
B3: Project Name | G3: Prepared by : | I3: Putrisya Novatiara Sonia | K3: Last Checkpoint | M3: 45279
B4: App Name : POS Application | D4: App Ver : | E4: 1.1.0 | G4: Prepared date : | I4: 45013 | K4: Last Progress | M4: 0
B5: Internal Testing/ SIT/ UAT | D5: Doc Ver : | E5: 1.1.0 | K5: Today Checkpoint | M5: =NOW() -> 46056.49
K6: Today Progress | M6: =E28 -> 0
B8: Feature | D8: TC Pass | E8: TC Fail | F8: TC Blocked | G8: Total TC | H8: Progress
B11: TC01 Login | D11: =SUM(Login!O3:O3) -> 0 | E11: =SUM(Login!$O$4:$O$4) -> 0 | F11: =SUM(Login!$O$5:$O$5) -> 0 | G11: =SUM(Login!$O$7:$O$7) -> 11 | H11: =(D11+E11+F11)/G11 -> 0
B12: TC02 Profile | D12: =SUM(Profile!$O$3:$O$3) -> 0 | E12: =SUM(Profile!$O$4:$O$4) -> 0 | F12: =SUM(Profile!$O$5:$O$5) -> 0 | G12: =SUM(Profile!$O$7:$O$7) -> 8 | H12: =(D12+E12+F12)/G12 -> 0
B13: TC03 Order Transaction | D13: =SUM(Order!$O$3:$O$3) -> 0 | E13: =SUM(Order!$O$4:$O$4) -> 0 | F13: =SUM(Order!$O$5:$O$5) -> 0 | G13: =SUM(Order!$O$7:$O$7) -> 23 | H13: =(D13+E13+F13)/G13 -> 0
B14: TC05 Product | D14: =SUM(Product!$O$3:$O$3) -> 0 | E14: =SUM(Product!$O$4:$O$4) -> 0 | F14: =SUM(Product!$O$5:$O$5) -> 0 | G14: =SUM(Product!$O$7:$O$7) -> 22 | H14: =(D14+E14+F14)/G14 -> 0
B15: TC06 Printer | D15: =SUM(printer!$O$3:$O$3) -> 0 | E15: =SUM(printer!$O$4:$O$4) -> 0 | F15: =SUM(printer!$O$5:$O$5) -> 0 | G15: =SUM(printer!$O$7:$O$7) -> 8 | H15: =(D15+E15+F15)/G15 -> 0
B16: TC07 Promo | D16: =SUM(Promo_product!$O$3:$O$3) -> 0 | E16: =SUM(Promo_product!$O$4:$O$4) -> 0 | F16: =SUM(Promo_product!$O$5:$O$5) -> 0 | G16: =SUM(Promo_product!$O$7:$O$7) -> 23 | H16: =(D16+E16+F16)/G16 -> 0
B17: TC011 Shift Log List | D17: =SUM(Shift_log_list!$O$3:$O$3) -> 0 | E17: =SUM(Shift_log_list!$O$4:$O$4) -> 0 | F17: =SUM(Shift_log_list!$O$5:$O$5) -> 0 | G17: =SUM(Shift_log_list!$O$7:$O$7) -> 8 | H17: =(D17+E17+F17)/G17 -> 0
B18: TC012 Product Management | D18: =SUM(Product_Management!$O$3:$O$3) -> 0 | E18: =SUM(Product_Management!$O$4:$O$4) -> 0 | F18: =SUM(Product_Management!$O$5:$O$5) -> 0 | G18: =SUM(Product_Management!$O$7:$O$7) -> 6 | H18: =(D18+E18+F18)/G18 -> 0
B19: Compliment | D19: =SUM(compliment!$O$3:$O$3) -> 0 | E19: =SUM(compliment!$O$4:$O$4) -> 0 | F19: =SUM(compliment!$O$5:$O$5) -> 0 | G19: =SUM(compliment!$O$7:$O$7) -> 1 | H19: =(D19+E19+F19)/G19 -> 0
B20: Daily report | D20: =SUM(daily_report!$O$3:$O$3) -> 0 | E20: =SUM(daily_report!$O$4:$O$4) -> 0 | F20: =SUM(daily_report!$O$5:$O$5) -> 0 | G20: =SUM(daily_report!$O$7:$O$7) -> 12 | H20: =(D20+E20+F20)/G20 -> 0
B21: Voucher | D21: =SUM(voucher!$O$3:$O$3) -> 0 | E21: =SUM(voucher!$O$4:$O$4) -> 0 | F21: =SUM(voucher!$O$5:$O$5) -> 0 | G21: =SUM(voucher!$O$7:$O$7) -> 5 | H21: =(D21+E21+F21)/G21 -> 0
B22: Store Config | D22: =SUM(Store_config!$O$3:$O$3) -> 0 | E22: =SUM(Store_config!$O$4:$O$4) -> 0 | F22: =SUM(Store_config!$O$5:$O$5) -> 0 | G22: =SUM(Store_config!$O$7:$O$7) -> 3 | H22: =(D22+E22+F22)/G22 -> 0
B23: Multiscreen | D23: =SUM(Multiscreen!$O$3:$O$3) -> 0 | E23: =SUM(Multiscreen!$O$4:$O$4) -> 0 | F23: =SUM(Multiscreen!$O$5:$O$5) -> 0 | G23: =SUM(Multiscreen!$O$7:$O$7) -> 9 | H23: =(D23+E23+F23)/G23 -> 0
B24: Scanner | D24: =SUM(scanner!$O$3:$O$3) -> 0 | E24: =SUM(scanner!$O$4:$O$4) -> 0 | F24: =SUM(scanner!$O$5:$O$5) -> 0 | G24: =SUM(scanner!$O$7:$O$7) -> 9 | H24: =(D24+E24+F24)/G24 -> 0
B26: Total | D26: =SUM(D11:D24) -> 0 | E26: =SUM(E11:E24) -> 0 | F26: =SUM(F11:F24) -> 0 | G26: =SUM(G11:G24) -> 148
C28: Success Percentage | D28: =D26/G26 -> 0 | E28: =(D26+E26+F26)/G26 -> 0 | H28: Testing Progress
C29: Failed Percentage | D29: =E26/G26 -> 0
C30: Blocked Percentage | D30: =F26/G26 -> 0

Sheet Login
B2: =SUM(O3:O5)/O7 -> 0 | H2: Project | I2: =[1]Cover!B3 -> Project Name | N2: Summary | O2: =SUM(O3:O5)/O7 -> 0 | Q2: Detail:
H3: Test Scenario | I3: =[1]Cover!B11 -> TC01 Login | N3: Pass | O3: =COUNTIF(K7:K42,1) -> 0 | Q3: Total Positif Case | R3: =COUNTIF(D8:D16,"Positive") -> 2
B4: Percentage | H4: Date | I4: dd/mm/yyyy | N4: Failed | O4: =COUNTIF(K7:K42,0) -> 0 | Q4: Total Negative Case | R4: =COUNTIF(D9:D16,"Negative") -> 1
N5: Blocked | O5: =COUNTIF(K9:K44,"Block") -> 0
B6: TC ID | C6: Test Scenario | D6: Type | E6: Precondition | F6: Test Data | G6: Test Procedure | I6: Expected Result | J6: Actual Result | K6: Test Result | L6: Notes | N6: Not Yet Tested | O6: =COUNTIF(K7:K42,".") -> 11
B7: ot | N7: Total Case | O7: =SUM(O3:O6) -> 11
B8: TC01_001 | C8: LOGIN | D8: Positive | E8: Berada pada halaman login | F8: device | G8: 1 | H8: Input device token | I8: 1. Berhasil login | K8: .
G9: 2 | H9: Input PIN | I9: 2. Masuk ke halaman home
G10: 4 | H10: Klik tombol Login
B11: TC01_003 | C11: Forgot Password | D11: Positive | E11: Berada pada halaman login | G11: 1 | H11: Tekan Forgot Password | I11: Menampilkan input email | L11: fitur tidak ada, forgot passord dari backoffice
G12: 2 | H12: Input e-mail | I12: Sesuai input
G13: 3 | H13: Input password baru | I13: Sesuai input
G14: 4 | H14: Login menggunakan password baru | I14: Login berhasil
B15: Negative case
B16: TC01_004 | C16: LOGIN dengan invalid device token | D16: Negative | E16: Berada pada halaman login | G16: 1 | H16: Input false device token | I16: shows error " device not found" | K16: .
B17: TC01_005 | C17: LOGIN dengan token yang sudah digunakan device lain | D17: Negative | E17: Berada pada halaman login | G17: 1 | H17: input device token active unutk device lain | I17: as inputted | K17: .
G18: 2 | H18: klik next | I18: showsh error "
B19: TC01_005 | C19: LOGIN dengan invalid pin lebih dari 3 kali | D19: Negative | E19: Berada pada halaman login | G19: 1 | H19: Input username | I19: 1. Gagal login | K19: .
G20: 2 | H20: Input password | I20: 2. Muncul warning : Please input username and password
G21: 3 | H21: Klik tombol Login
B22: TC01_006 | C22: LOGIN user with old pin | D22: Negative | E22: Berada pada halaman login | G22: 1 | H22: Change password | I22: Password berhasil diubah | K22: .
G23: 2 | H23: Logout from application | I23: Logout berhasil
G24: 3 | H24: Login with old password | I24: Login gagal
B25: TC01_007 | C25: LOGIN Login with deleted user | D25: Negative | E25: Berada pada halaman login | G25: 1 | H25: Delete user | I25: Data berhasil dihapus | K25: .
G26: 2 | H26: Logout from application | I26: Logout berhasil
G27: 3 | H27: Login with deleted user | I27: Login gagal
B28: TC01_008 | C28: LOGIN Login with inactive device token | D28: Negative | E28: Berada pada halaman login | G28: 1 | H28: change status user (inactive) | I28: Data berhasil diupdate | K28: .
G29: 2 | H29: Logout from application | I29: Logout berhasil
G30: 3 | H30: Login with deleted user | I30: Login gagal
B31: TC01_008 | C31: LOGIN Login with inactive user | D31: Negative | E31: Berada pada halaman login | G31: 1 | H31: change status user (inactive) | I31: Data berhasil diupdate | K31: .
G32: 2 | H32: Logout from application | I32: Logout berhasil
G33: 3 | H33: Login with deleted user | I33: Login gagal
B34: TC01_008 | C34: LOGIN login with new device token | D34: Negative | E34: Berada pada halaman login | G34: 1 | H34: change status user (inactive) | I34: Data berhasil diupdate | K34: .
G35: 2 | H35: Logout from application | I35: Logout berhasil
G36: 3 | H36: Login with deleted user | I36: Login gagal
B37: TC01_008 | C37: unregister device - register | D37: Negative | E37: Berada pada input pin | G37: 1 | H37: klik unregister device | I37: Data berhasil diupdate | K37: .
G38: 2 | H38: input new device token | I38: success direct ke halaman login
G39: 3 | H39: input pin | I39: direct ke homepage
C40: update apps | G40: 1 | H40: install applikasi v2.0.0 | K40: . | L40: gagal update
G41: 2 | H41: update aplikasi to v2.2.0
...

Sheet Profile
B2: =SUM(O3:O4)/SUM(O6:O6) -> 0 | H2: Project | L2: Pass [1] | N2: Summary | O2: =SUM(O3:O5)/O7 -> 0 | Q2: Detail:
H3: Test Scenario | L3: Fail [0] | N3: Pass | O3: =COUNTIF(K7:K83,1) -> 0 | Q3: Total Positif Case | R3: =COUNTIF(D8:D82,"Positive") -> 9
B4: Percentage | H4: Date | L4: Not yet tested [blank] | N4: Failed | O4: =COUNTIF(K7:K83,0) -> 0 | Q4: Total Negative Case | R4: =COUNTIF(D9:D82,"Negative") -> 0
N5: Blocked | O5: =COUNTIF(K9:K85,"Block") -> 0
B6: TC ID | C6: Test Scenario | D6: Type | E6: Precondition | F6: Test Data | G6: Test Procedure | I6: Expected Result | J6: Actual Result | K6: Test Result | L6: Comment | N6: Not Yet Tested | O6: =COUNTIF(K7:K83,".") -> 8
N7: Total Case | O7: =SUM(O3:O6) -> 8
B8: Positive Case
B9: TC02_002 | C9: detail First Name | D9: Positive | G9: 1 | H9: Klik Profile | I9: Menampilkan informasi user | J9: Menampilkan informasi user | K9: .
G10: 2 | H10: first name sesuai dengan setup back office | I10: data sesuai | J10: Menampilkan sesuai input
B11: TC02_003 | C11: detail store name | D11: Positive | G11: 1 | H11: Klik Profile | I11: Menampilkan informasi user | J11: Menampilkan informasi user | K11: .
G12: 2 | H12: data sesuai dengan setup back office | I12: data sesuai | J12: Menampilkan sesuai input
B13: TC02_003 | C13: detail address | D13: Positive | G13: 1 | H13: Klik Profile | I13: Menampilkan informasi user | J13: Menampilkan informasi user | K13: .
G14: 2 | H14: data sesuai dengan setup back office | I14: data sesuai | J14: Menampilkan sesuai input
B15: TC02_003 | C15: detail rounding type | D15: Positive | G15: 1 | H15: Klik Profile | I15: Menampilkan informasi user | J15: Menampilkan informasi user | K15: .
G16: 2 | H16: data sesuai dengan setup back office | I16: data sesuai | J16: Menampilkan sesuai input
B17: TC02_004 | C17: detail Phone Number | D17: Positive | G17: 1 | H17: Klik Profile | I17: Menampilkan informasi user | K17: .
G18: 2 | H18: data sesuai dengan setup back office | I18: data sesuai
B19: TC02_006 | C19: Verify Email via Account Profile | D19: Positive | G19: 1 | H19: Klik Profile | I19: Menampilkan informasi user
G20: 2 | H20: data sesuai dengan setup back office | I20: data sesuai
G21: 3 | H21: Klik tombol Verifikasi Email | I21: Email verifikasi akan dikirimkan
B22: TC02_006 | C22: detail promo | D22: Positive | G22: 1 | H22: Klik Profile | I22: Menampilkan informasi user | K22: .
G23: 2 | H23: data sesuai dengan setup back office | I23: data sesuai
G24: 3 | H24: Klik tombol Verifikasi Email | I24: Email verifikasi akan dikirimkan
B25: TC02_006 | C25: product card config | D25: Positive | F25: image | G25: 1 | H25: change card config | I25: Menampilkan informasi user | K25: . | L25: product list config akan terapply di halaman product tanpa ada order yang active.
F26: card | G26: 2 | H26: refresh in the homepage menu ( product menu) | I26: product lsit will change
F27: list
B28: TC02_006 | C28: product list config | D28: Positive | F28: pagination | G28: 1 | H28: change card config | I28: Menampilkan informasi user | K28: . | L28: pagination - load product per 10 prdoduct sync - load product sekaligus limitasi - ketika product lebih dari 1000 dan memilih sync, aplikasi akan endless loading sehingga untuk saat ini default akan diarahkan untuk menggunakan pagination
F29: sync | G29: 2 | H29: refresh in the homepage menu ( product menu) | I29: sistem menampilkan product berubsh
B30: Negative Case

Sheet Product
B2: =SUM(O3:O4)/SUM(O6:O6) -> 0 | H2: Project | L2: Pass [1] | N2: Summary | O2: =SUM(O3:O5)/O7 -> 0 | Q2: Detail:
H3: Test Scenario | L3: Fail [0] | N3: Pass | O3: =COUNTIF(K7:K121,1) -> 0 | Q3: Total Positif Case | R3: =COUNTIF(D8:D120,"Positive") -> 18
B4: Percentage | H4: Date | L4: Not yet tested [blank] | N4: Failed | O4: =COUNTIF(K7:K121,0) -> 0 | Q4: Total Negative Case | R4: =COUNTIF(D9:D120,"Negative") -> 4
N5: Blocked | O5: =COUNTIF(K9:K123,"Block") -> 0
B6: TC ID | C6: Test Scenario | D6: Type | E6: Precondition | F6: Test Data | G6: Test Procedure | I6: Expected Result | J6: Actual Result | K6: Test Result | L6: Comment | N6: Not Yet Tested | O6: =COUNTIF(K7:K121,".") -> 22
N7: Total Case | O7: =SUM(O3:O6) -> 22
B8: Case Sale On Us
B9: TC05_001 | C9: add product | D9: Positive | G9: 1 | H9: Tambah product di back office | I9: berhasil | K9: .
G10: 2 | H10: langsung refresh di menu product | I10: menampilkan product list
G11: 3 | H11: product bertambah | I11: product berhasil bertambah
B12: TC05_002 | C12: Edit product | D12: Positive | G12: 1 | H12: edit product di back office | I12: Menampilkan informasi user | K12: .
G13: 2 | H13: langsung refresh di menu product | I13: Menampilkan sesuai input
G14: 3 | H14: product berhasil teredit | I14: Data berhasil diubah
B15: TC05_003 | C15: delete product | D15: Positive | G15: 1 | H15: delete product di back office | I15: Menampilkan informasi user | K15: .
G16: 2 | H16: langsung refresh di menu product | I16: Menampilkan sesuai input
G17: 3 | H17: product berhasil terdelete - produk tidak muncul | I17: produk tidak muncul
B18: TC05_004 | C18: add variant | D18: Positive | G18: 1 | H18: Tambah variant di back office | I18: berhasil | K18: .
G19: 2 | H19: langsung refresh di menu product | I19: menampilkan product list
G20: 3 | H20: variant bertambah | I20: variant berhasil bertambah dan muncul
B21: TC05_004 | C21: edit variant | D21: Positive | G21: 1 | H21: edit variant di back office | I21: berhasil | K21: .
G22: 2 | H22: langsung refresh di menu product | I22: menampilkan product list
G23: 3 | H23: variant berhasil terubah | I23: perubahan sesuai config
B24: TC05_006 | C24: delete variant | D24: Positive | G24: 1 | H24: delete variant di back office | I24: berhasil | K24: .
G25: 2 | H25: langsung refresh di menu product | I25: menampilkan product list
G26: 3 | H26: variant berhasil terdelete | I26: perubahan sesuai config
B27: TC05_001 | C27: add product option mandatory | D27: Positive | G27: 1 | H27: Tambah product option di back office | I27: berhasil | K27: .
G28: 2 | H28: langsung refresh di menu product | I28: menampilkan product list
G29: 3 | H29: product option bertambah | I29: product option berhasil bertambah dan muncul
B30: TC05_002 | C30: Edit product option manotory | D30: Positive | G30: 1 | H30: edit product option di back office | I30: berhasil | K30: .
G31: 2 | H31: langsung refresh di menu product | I31: menampilkan product list
G32: 3 | H32: product option berhasil terubah | I32: perubahan sesuai config
B33: TC05_003 | C33: delete product option mandatory | D33: Positive | G33: 1 | H33: delete product option di back office | I33: berhasil | K33: .
G34: 2 | H34: langsung refresh di menu product | I34: menampilkan product list
G35: 3 | H35: product option berhasil terdelete | I35: perubahan sesuai config
B36: TC05_001 | C36: add stock | D36: Positive | G36: 1 | H36: Tambah stock di back office | I36: berhasil | K36: .
G37: 2 | H37: langsung refresh di menu product | I37: menampilkan product list
G38: 3 | H38: stock bertambah | I38: stock berhasil bertambah dan muncul
B39: TC05_002 | C39: edit stock | D39: Positive | G39: 1 | H39: edit stock di back office | I39: berhasil | K39: .
G40: 2 | H40: langsung refresh di menu product | I40: menampilkan product list
G41: 3 | H41: stock berhasil terubah | I41: perubahan sesuai config
...

Sheet Product_Management
B2: =SUM(O3:O5)/O7 -> 0 | H2: Project | I2: =[1]Cover!B3 -> Project Name | N2: Summary | O2: =SUM(O3:O5)/O7 -> 0 | Q2: Detail:
H3: Test Scenario | I3: =[1]Cover!B11 -> TC01 Login | N3: Pass | O3: =COUNTIF(K7:K27,1) -> 0 | Q3: Total Positif Case | R3: =COUNTIF(D8:D20,"Positive") -> 1
B4: Percentage | H4: Date | I4: dd/mm/yyyy | N4: Failed | O4: =COUNTIF(K7:K27,0) -> 0 | Q4: Total Negative Case | R4: =COUNTIF(D9:D20,"Negative") -> 3
N5: Blocked | O5: =COUNTIF(K9:K29,"Block") -> 0
B6: TC ID | C6: Test Scenario | D6: Type | E6: Precondition | F6: Test Data | G6: Test Procedure | I6: Expected Result | J6: Actual Result | K6: Test Result | L6: Notes | N6: Not Yet Tested | O6: =COUNTIF(K7:K27,".") -> 6
B7: ot | N7: Total Case | O7: =SUM(O3:O6) -> 6
B8: TC03_001 | C8: UPDATE STOCK WITH VALID NUMBER [STOCK>0] | D8: Positive | G8: 1 | H8: klik product management | I8: Menampilkan sesuai category | K8: .
G9: 2 | H9: ubah stock | I9: menmapilkan product
G10: 3 | H10: cek penggunaan produtc list | I10: muncul pop up detail product
B11: Negative case
B12: TC03_005 | C12: UPDATE STOCK WITH INVALID VALUE [STOCK <= 0] | D12: Negative | G12: 1 | H12: klik product management | I12: Muncul pilihan untuk paymet method | K12: .
G13: 2 | H13: ubah stock | I13: Menampilkan list produk
G14: 3 | H14: input 0 | I14: muncul error msg
B15: TC03_005 | C15: UPDATE STOCK WITH INVALID VALUE [ALPHABET] | D15: Negative | G15: 1 | H15: klik product management | I15: Muncul pilihan untuk paymet method | K15: .
G16: 2 | H16: ubah stock | I16: Menampilkan list produk
G17: 3 | H17: input alfabet | I17: muncul error msg
B18: TC03_005 | C18: UPDATE STOCK WITH EMPTY DATA | D18: Negative | G18: 1 | H18: klik product management | I18: Muncul pilihan untuk paymet method | K18: .
G19: 2 | H19: ubah stock | I19: Menampilkan list produk
G20: 3 | H20: input kosong | I20: muncul error msg
B21: TC03_005 | C21: edit stock lebih sedikit | D21: Negative | G21: 1 | H21: klik product management | I21: Muncul pilihan untuk paymet method | K21: .
G22: 2 | H22: ubah stock | I22: Menampilkan list produk
G23: 3 | H23: input kosong | I23: muncul error msg
B24: TC03_005 | C24: empty stock | D24: Negative | G24: 1 | H24: klik product management | I24: Muncul pilihan untuk paymet method | K24: .
G25: 2 | H25: klik empty stock | I25: Menampilkan list produk
G26: 3 | H26: cek di product list | I26: muncul error msg

Sheet Order
B2: =SUM(O3:O5)/O7 -> 0 | H2: Project | I2: =[2]Cover!B3 -> #REF! | N2: Summary | O2: =SUM(O3:O5)/O7 -> 0 | Q2: Detail:
H3: Test Scenario | I3: =[2]Cover!B11 -> #REF! | N3: Pass | O3: =COUNTIF(K7:K127,1) -> 0 | Q3: Total Positif Case | R3: =COUNTIF(D8:D114,"Positive") -> 16
B4: Percentage | H4: Date | I4: dd/mm/yyyy | N4: Failed | O4: =COUNTIF(K7:K127,0) -> 0 | Q4: Total Negative Case | R4: =COUNTIF(D8:D114,"Negative") -> 5
N5: Blocked | O5: =COUNTIF(K8:K129,"Block") -> 0
B6: TC ID | C6: Test Scenario | D6: Type | E6: Precondition | F6: Test Data | G6: Test Procedure | I6: Expected Result | J6: Actual Result | K6: Test Result | L6: Notes | N6: Not Yet Tested | O6: =COUNTIF(K7:K127,".") -> 23
B7: ot | N7: Total Case | O7: =SUM(O3:O6) -> 23
B8: TC03_001 | C8: Order product (Takeaway - cash) | D8: Positive | F8: Order 1 product (food) | G8: 1 | H8: klik Category | I8: Menampilkan sesuai category | K8: .
F9: Order 2 product (food n drink) | G9: 2 | H9: klik Subcategory | I9: menmapilkan product
F10: Order kombinasi | G10: 3 | H10: klik product | I10: muncul pop up detail product
G11: 4 | H11: Add count product | I11: jumlah product bertambahberkurang
G12: 5 | H12: Add add ons | I12: Muncul button biru di add ons yang dipilih
G13: 6 | H13: Klik Add Order | I13: muncul detail pada sisi kanan tampilan
G14: 7 | H14: Klik Go To Payment | I14: Muncul bagian untuk memilih transaction
G15: 8 | H15: Pilih Payment method
G16: 9 | H16: Klik Proceed with payment
G17: 10 | H17: Klik Add Order
B18: TC03_001 | C18: Order product (takeaway - QRIS) | D18: Positive | F18: Order 1 product (food) | G18: 1 | H18: klik Category | I18: Menampilkan sesuai category | K18: .
F19: Order 2 product (food n drink) | G19: 2 | H19: klik Subcategory | I19: menmapilkan product
F20: order kombinasi | G20: 3 | H20: klik product | I20: muncul pop up detail product
G21: 4 | H21: Add count product | I21: jumlah product bertambahberkurang
G22: 5 | H22: Add add ons | I22: Muncul button biru di add ons yang dipilih
G23: 6 | H23: Klik Add Order | I23: muncul detail pada sisi kanan tampilan
G24: 7 | H24: Klik Go To Payment | I24: Muncul bagian untuk memilih transaction
G25: 8 | H25: Pilih Payment method
G26: 9 | H26: Klik Proceed with payment
G27: 10 | H27: Klik Add Order
B28: TC03_001 | C28: Order product (Takeaway - CREDIT) | D28: Positive | F28: Order 1 product (food) | G28: 1 | H28: klik Category | I28: Menampilkan sesuai category | L28: credit beum support
F29: Order 2 product (food n drink) | G29: 2 | H29: klik Subcategory | I29: menmapilkan product
F30: Order kombinasi | G30: 3 | H30: klik product | I30: muncul pop up detail product
G31: 4 | H31: Add count product | I31: jumlah product bertambahberkurang
G32: 5 | H32: Add add ons | I32: Muncul button biru di add ons yang dipilih
G33: 6 | H33: Klik Add Order | I33: muncul detail pada sisi kanan tampilan
G34: 7 | H34: Klik Go To Payment | I34: Muncul bagian untuk memilih transaction
G35: 8 | H35: Pilih Payment method
G36: 9 | H36: Klik Proceed with payment
G37: 10 | H37: Klik Add Order
B38: TC03_001 | C38: Order product (takeaway - EDC) | D38: Positive | F38: Order 1 product (food) | G38: 1 | H38: klik Category | I38: Menampilkan sesuai category | K38: .
F39: Order 2 product (food n drink) | G39: 2 | H39: klik Subcategory | I39: menmapilkan product
F40: order kombinasi | G40: 3 | H40: klik product | I40: muncul pop up detail product
G41: 4 | H41: Add count product | I41: jumlah product bertambahberkurang
...

Sheet voucher
B2: =SUM(O3:O4)/SUM(O6:O6) -> 0 | H2: Project | L2: Pass [1] | N2: Summary | O2: =SUM(O3:O5)/O7 -> 0 | Q2: Detail:
H3: Test Scenario | L3: Fail [0] | N3: Pass | O3: =COUNTIF(K7:K97,1) -> 0 | Q3: Total Positif Case | R3: =COUNTIF(D8:D96,"Positive") -> 4
B4: Percentage | H4: Date | L4: Not yet tested [blank] | N4: Failed | O4: =COUNTIF(K7:K97,0) -> 0 | Q4: Total Negative Case | R4: =COUNTIF(D9:D96,"Negative") -> 4
N5: Blocked | O5: =COUNTIF(K9:K99,"Block") -> 0
B6: TC ID | C6: Test Scenario | D6: Type | E6: Precondition | F6: Test Data | G6: Test Procedure | I6: Expected Result | J6: Actual Result | K6: Test Result | L6: Comment | N6: Not Yet Tested | O6: =COUNTIF(K7:K97,".") -> 5
N7: Total Case | O7: =SUM(O3:O6) -> 5
B8: Positive Case
B9: TC07_001 | C9: Penggunaan Voucher | D9: Positive | G9: 1 | H9: klik go to payment ( 1 transaksi) | I9: menampilkan page order | K9: .
G10: 2 | H10: klik voucher | I10: menampilkan field voucher
G11: 3 | H11: input detail voucher | I11: sesuai input
G12: 4 | H12: klik save | I12: berhasil terrecord
G13: 5 | H13: klik add | I13: berhaisl tertambahkan pada amount transaksi
B14: TC07_002 | C14: Penggunaan Voucher >1 transaksi | D14: Positive | G14: 1 | H14: klik go to payment ( 1 transaksi) | I14: menampilkan page order | K14: .
G15: 2 | H15: klik voucher | I15: menampilkan field voucher
G16: 3 | H16: input detail voucher | I16: sesuai input
G17: 4 | H17: klik save | I17: berhasil terrecord
G18: 5 | H18: klik add | I18: berhaisl tertambahkan pada amount transaksi
B19: TC07_002 | C19: dgn voucher code yang sama | D19: Positive | G19: 1 | H19: klik go to payment ( 1 transaksi) | I19: menampilkan page order | L19: belum ada pengecekan
G20: 2 | H20: klik voucher | I20: menampilkan field voucher
G21: 3 | H21: input detail voucher | I21: sesuai input
G22: 4 | H22: klik save | I22: berhasil terrecord
G23: 5 | H23: klik add | I23: berhaisl tertambahkan pada amount transaksi
B24: TC07_003 | C24: promo pos transaksi + promo product +promo pos+ promo galileo + voucher | D24: Positive | G24: 1 | H24: klik go to payment ( 1 transaksi) | I24: menampilkan page order | K24: . | L24: galileo endless loading
G25: 2 | H25: klik voucher | I25: menampilkan field voucher
G26: 3 | H26: input detail voucher | I26: sesuai input
G27: 4 | H27: klik save | I27: berhasil terrecord
G28: 5 | H28: klik add | I28: berhaisl tertambahkan pada amount transaksi
B29: Negative Case
B30: TC07_028 | C30: apply voucher sampai nilai transaki <=0 <voucher pvs> | D30: Negative | E30: order summary page | G30: 1 | H30: add voucher hingga amount = 0 | I30: add voucher berhasil | L30: tidak support
G31: 2 | H31: cek prder summary | I31: total amount rp = 0
G32: 3 | H32: choose paymemt method | I32: transaksi berhasil
B33: TC07_029 | C33: apply voucher melebihi batas voucher | D33: Negative | G33: 1 | H33: set batas voucher di back office | I33: setup berhasil | K33: .
G34: 2 | H34: add voucher melebihi batas voucher | I34: showsh error
B35: TC07_029 | C35: empty field | D35: Negative | G35: 1 | K35: .
G36: 2
G37: 3
G38: 4
G39: 5
B40: TC07_030 | C40: apply promo sampai nilai transaki <=0 <promo pvs + galileo> | D40: Negative | G40: 1 | L40: tidak support
G41: 2
...

Sheet Promo_product
B2: =SUM(O3:O4)/SUM(O6:O6) -> 0 | H2: Project | L2: Pass [1] | N2: Summary | O2: =SUM(O3:O5)/O7 -> 0 | Q2: Detail:
H3: Test Scenario | L3: Fail [0] | N3: Pass | O3: =COUNTIF(K7:K291,1) -> 0 | Q3: Total Positif Case | R3: =COUNTIF(D8:D290,"Positive") -> 23
B4: Percentage | H4: Date | L4: Not yet tested [blank] | N4: Failed | O4: =COUNTIF(K7:K291,0) -> 0 | Q4: Total Negative Case | R4: =COUNTIF(D29:D290,"Negative") -> 31
N5: Blocked | O5: =COUNTIF(K29:K293,"Block") -> 0
B6: TC ID | C6: Test Scenario | D6: Type | E6: Precondition | F6: Test Data | G6: Test Procedure | I6: Expected Result | J6: Actual Result | K6: Test Result | L6: Comment | N6: Not Yet Tested | O6: =COUNTIF(K7:K291,".") -> 23
N7: Total Case | O7: =SUM(O3:O6) -> 23
B8: Positive Case
B9: TC07_001 | C9: add Promo Galileo DINE - IN <percentage> | D9: Positive | G9: 1 | H9: tambah product di back office | I9: berhasil | K9: .
G10: 2 | H10: Input Current Password | I10: Menampilkan masking
G11: 3 | H11: Input New Password | I11: Menampilkan masking
G12: 4 | H12: Input Confirn Password | I12: Menampilkan masking
G13: 5 | H13: Klik Change Password | I13: > User akan terlogout > Login berhasil dengan password baru | O13: Note
B14: TC07_001 | C14: add Promo Galileo by apps | D14: Positive | G14: 1 | H14: tambah product di back office | I14: berhasil | K14: .
G15: 2 | H15: Input Current Password | I15: Menampilkan masking
G16: 3 | H16: Input New Password | I16: Menampilkan masking
G17: 4 | H17: Input Confirn Password | I17: Menampilkan masking
G18: 5 | H18: Klik Change Password | I18: > User akan terlogout > Login berhasil dengan password baru
B19: TC07_002 | C19: add Promo Galileo by wa | D19: Positive | G19: 1 | H19: tambah product di back office | I19: berhasil | K19: .
G20: 2 | H20: Input Current Password | I20: Menampilkan masking
G21: 3 | H21: Input New Password | I21: Menampilkan masking
G22: 4 | H22: Input Confirn Password | I22: Menampilkan masking
G23: 5 | H23: Klik Change Password | I23: > User akan terlogout > Login berhasil dengan password baru
B24: TC07_003 | C24: add Promo Galileo by sms | D24: Positive | G24: 1 | H24: tambah product di back office | I24: berhasil | K24: .
G25: 2 | H25: Input Current Password | I25: Menampilkan masking
G26: 3 | H26: Input New Password | I26: Menampilkan masking
G27: 4 | H27: Input Confirn Password | I27: Menampilkan masking
G28: 5 | H28: Klik Change Password | I28: > User akan terlogout > Login berhasil dengan password baru
B29: TC07_001 | C29: add Promo Galileo non member | D29: Positive | G29: 1 | H29: tambah product di back office | I29: berhasil | K29: . | L29: promo non member dengan input nomor member masih meminta challenge code
G30: 2 | H30: Input Current Password | I30: Menampilkan masking
G31: 3 | H31: Input New Password | I31: Menampilkan masking
G32: 4 | H32: Input Confirn Password | I32: Menampilkan masking
G33: 5 | H33: Klik Change Password | I33: > User akan terlogout > Login berhasil dengan password baru
B34: TC07_002 | C34: add Promo Galileo galielo member | D34: Positive | G34: 1 | H34: tambah product di back office | I34: berhasil | K34: .
G35: 2 | H35: Input Current Password | I35: Menampilkan masking
G36: 3 | H36: Input New Password | I36: Menampilkan masking
G37: 4 | H37: Input Confirn Password | I37: Menampilkan masking
G38: 5 | H38: Klik Change Password | I38: > User akan terlogout > Login berhasil dengan password baru
B39: TC07_003 | C39: add Promo Galileo loyalty program member | D39: Positive | G39: 1 | H39: tambah product di back office | I39: berhasil | K39: .
G40: 2 | H40: Input Current Password | I40: Menampilkan masking
G41: 3 | H41: Input New Password | I41: Menampilkan masking
...

Sheet Shift_log_list
B2: =SUM(O3:O4)/SUM(O6:O6) -> 0 | H2: Project | L2: Pass [1] | N2: Summary | O2: =SUM(O3:O5)/O7 -> 0 | Q2: Detail:
H3: Test Scenario | L3: Fail [0] | N3: Pass | O3: =COUNTIF(K7:K99,1) -> 0 | Q3: Total Positif Case | R3: =COUNTIF(D8:D98,"Positive") -> 3
B4: Percentage | H4: Date | L4: Not yet tested [blank] | N4: Failed | O4: =COUNTIF(K7:K99,0) -> 0 | Q4: Total Negative Case | R4: =COUNTIF(D9:D98,"Negative") -> 5
N5: Blocked | O5: =COUNTIF(K9:K101,"Block") -> 0
B6: TC ID | C6: Test Scenario | D6: Type | E6: Precondition | F6: Test Data | G6: Test Procedure | I6: Expected Result | J6: Actual Result | K6: Test Result | L6: Comment | N6: Not Yet Tested | O6: =COUNTIF(K7:K99,".") -> 8
N7: Total Case | O7: =SUM(O3:O6) -> 8
B8: Case Sale On Us
B9: TC11_001 | C9: START SHIFT | D9: Positive | G9: 1 | H9: KLIK Shift handover list | I9: Menamppilkan page shift log | K9: . | L9: gagal end shift
G10: 2 | H10: klik start shift | I10: menampilkan pop up field untuk mengisi deposit cash
G11: 3 | H11: input deposit | I11: sesuai inputan
G12: 1 | H12: klik ok | I12: detail sesuai
B13: TC11_001 | C13: START SHIFT kedua | D13: Positive | G13: 1 | H13: KLIK Shift handover list | I13: Menamppilkan page shift log | K13: . | L13: gagal end shift
G14: 2 | H14: klik start shift | I14: menampilkan pop up field untuk mengisi deposit cash
G15: 3 | H15: input deposit | I15: sesuai inputan
G16: 1 | H16: klik ok | I16: detail sesuai
B17: TC11_001 | C17: END SHIFT | D17: Positive | G17: 1 | H17: KLIK Shift handover list | I17: Menamppilkan page shift log | K17: . | L17: gagal end shift
G18: 2 | H18: klik END shift | I18: menampilkan pop up field untuk mengisi deposit cash
G19: 3 | H19: input deposit | I19: sesuai inputan
G20: 1 | H20: klik ok | I20: detail sesuai
B21: Negative Case
B22: TC11_001 | C22: INSERT STARTING CASH <NON - INTEGER> | D22: Negative | G22: 1 | H22: Klik Change Password | I22: Menampilkan field password | K22: .
G23: 2 | H23: Input Current Wrong Password | I23: Menampilkan masking
G24: 3 | H24: Input New Password | I24: Menampilkan masking
G25: 4 | H25: Input Confirm Password | I25: Menampilkan masking
G26: 5 | H26: Klik Change Password | I26: Notifikasi gagal
B27: TC11_001 | C27: INSERT STARTING CASH < INTEGER <=0 > | D27: Negative | G27: 1 | H27: Klik Change Password | I27: Menampilkan field password | K27: .
G28: 2 | H28: Input Current Wrong Password | I28: Menampilkan masking
G29: 3 | H29: Input New Password | I29: Menampilkan masking
G30: 4 | H30: Input Confirm Password | I30: Menampilkan masking
G31: 5 | H31: Klik Change Password | I31: Notifikasi gagal
B32: TC11_001 | C32: INSERT STARTING CASH <INTEGER > 100000000000> | D32: Negative | G32: 1 | H32: Klik Change Password | I32: Menampilkan field password | K32: .
G33: 2 | H33: Input Current Wrong Password | I33: Menampilkan masking
G34: 3 | H34: Input New Password | I34: Menampilkan masking
G35: 4 | H35: Input Confirm Password | I35: Menampilkan masking
G36: 5 | H36: Klik Change Password | I36: Notifikasi gagal
B37: TC11_001 | C37: LOGOUT APAKAH END SHIFT? | D37: Negative | G37: 1 | H37: Klik Change Password | I37: Menampilkan field password | K37: .
G38: 2 | H38: Input Current Wrong Password | I38: Menampilkan masking
G39: 3 | H39: Input New Password | I39: Menampilkan masking
G40: 4 | H40: Input Confirm Password | I40: Menampilkan masking
G41: 5 | H41: Klik Change Password | I41: Notifikasi gagal
...

Sheet compliment
B2: =SUM(O3:O5)/O7 -> 0 | H2: Project | I2: =[2]Cover!B3 -> #REF! | N2: Summary | O2: =SUM(O3:O5)/O7 -> 0 | Q2: Detail:
H3: Test Scenario | I3: =[2]Cover!B11 -> #REF! | N3: Pass | O3: =COUNTIF(K7:K48,1) -> 0 | Q3: Total Positif Case | R3: =COUNTIF(D8:D27,"Positive") -> 2
B4: Percentage | H4: Date | I4: dd/mm/yyyy | N4: Failed | O4: =COUNTIF(K7:K48,0) -> 0 | Q4: Total Negative Case | R4: =COUNTIF(D9:D27,"Negative") -> 0
N5: Blocked | O5: =COUNTIF(K9:K50,"Block") -> 0
B6: TC ID | C6: Test Scenario | D6: Type | E6: Precondition | F6: Test Data | G6: Test Procedure | I6: Expected Result | J6: Actual Result | K6: Test Result | L6: Notes | N6: Not Yet Tested | O6: =COUNTIF(K7:K48,".") -> 1
B7: ot | N7: Total Case | O7: =SUM(O3:O6) -> 1
B8: TC03_001 | C8: compliment ( 1 produk) | D8: Positive | G8: 1 | H8: klik Category | I8: Menampilkan sesuai category | L8: karena amount sampai 0, tidak bisa di proses
G9: 2 | H9: klik Subcategory | I9: menmapilkan product
G10: 3 | H10: klik product | I10: muncul pop up detail product
G11: 4 | H11: Add count product | I11: jumlah product bertambahberkurang
G12: 5 | H12: Add add ons | I12: Muncul button biru di add ons yang dipilih
G13: 6 | H13: Klik Add Order | I13: muncul detail pada sisi kanan tampilan
G14: 7 | H14: Klik Go To Payment | I14: Muncul bagian untuk memilih transaction
G15: 8 | H15: Pilih Payment method
G16: 9 | H16: Klik Proceed with payment
G17: 10 | H17: Klik Add Order
B18: TC03_002 | C18: compliment ( 2 produk) | D18: Positive | G18: 1 | H18: klik Category | I18: Menampilkan sesuai category | K18: .
G19: 2 | H19: klik Subcategory | I19: menmapilkan product
G20: 3 | H20: klik product | I20: muncul pop up detail product
G21: 4 | H21: Add count product | I21: jumlah product bertambahberkurang
G22: 5 | H22: Add add ons | I22: Muncul button biru di add ons yang dipilih
G23: 6 | H23: Klik Add Order | I23: muncul detail pada sisi kanan tampilan
G24: 7 | H24: Klik Go To Payment | I24: Muncul bagian untuk memilih transaction
G25: 8 | H25: Pilih Payment method
G26: 9 | H26: Klik Proceed with payment
G27: 10 | H27: Klik Add Order
B28: TC03_002 | C28: compliment kemudian split bill | D28: Positive | G28: 1 | H28: klik Category | I28: Menampilkan sesuai category
G29: 2 | H29: klik Subcategory | I29: menmapilkan product
G30: 3 | H30: klik product | I30: muncul pop up detail product
G31: 4 | H31: Add count product | I31: jumlah product bertambahberkurang
G32: 5 | H32: Add add ons | I32: Muncul button biru di add ons yang dipilih
G33: 6 | H33: Klik Add Order | I33: muncul detail pada sisi kanan tampilan
G34: 7 | H34: Klik Go To Payment | I34: Muncul bagian untuk memilih transaction
G35: 8 | H35: Pilih Payment method
G36: 9 | H36: Klik Proceed with payment
G37: 10 | H37: Klik Add Order
B38: TC03_002 | C38: compliment kemudian move item | D38: Positive | G38: 1 | H38: klik Category | I38: Menampilkan sesuai category
G39: 2 | H39: klik Subcategory | I39: menmapilkan product
G40: 3 | H40: klik product | I40: muncul pop up detail product
G41: 4 | H41: Add count product | I41: jumlah product bertambahberkurang
...

Sheet daily_report
B2: =SUM(O3:O5)/O7 -> 0 | H2: Project | I2: =[1]Cover!B3 -> Project Name | N2: Summary | O2: =SUM(O3:O5)/O7 -> 0 | Q2: Detail:
H3: Test Scenario | I3: =[1]Cover!B11 -> TC01 Login | N3: Pass | O3: =COUNTIF(K7:K56,1) -> 0 | Q3: Total Positif Case | R3: =COUNTIF(D8:D43,"Positive") -> 10
B4: Percentage | H4: Date | I4: dd/mm/yyyy | N4: Failed | O4: =COUNTIF(K7:K56,0) -> 0 | Q4: Total Negative Case | R4: =COUNTIF(D9:D43,"Negative") -> 0
N5: Blocked | O5: =COUNTIF(K9:K58,"Block") -> 0
B6: TC ID | C6: Test Scenario | D6: Type | E6: Precondition | F6: Test Data | G6: Test Procedure | I6: Expected Result | J6: Actual Result | K6: Test Result | L6: Notes | N6: Not Yet Tested | O6: =COUNTIF(K7:K56,".") -> 12
B7: ot | N7: Total Case | O7: =SUM(O3:O6) -> 12
B8: TC03_001 | C8: grand total | D8: Positive | G8: 1 | H8: klik daily report | I8: Menampilkan sesuai category | K8: .
G9: 2 | H9: amount sesuai | I9: menmapilkan product
B10: TC03_001 | C10: total amount | D10: Positive | G10: 1 | H10: klik daily report | I10: Menampilkan sesuai category | K10: .
G11: 2 | H11: amount sesuai | I11: menmapilkan product
B12: TC03_001 | C12: service charger | D12: Positive | G12: 1 | H12: klik daily report | I12: Menampilkan sesuai category | K12: .
G13: 2 | H13: amount sesuai | I13: menmapilkan product
B14: TC03_001 | C14: PB1 | D14: Positive | G14: 1 | H14: klik daily report | I14: Menampilkan sesuai category | K14: .
G15: 2 | H15: amount sesuai | I15: menmapilkan product
B16: TC03_001 | C16: Promo POS | D16: Positive | G16: 1 | H16: klik daily report | I16: Menampilkan sesuai category | K16: .
G17: 2 | H17: amount sesuai | I17: menmapilkan product
B18: TC03_001 | C18: Promo galileo | D18: Positive | G18: 1 | H18: klik daily report | I18: Menampilkan sesuai category | K18: .
G19: 2 | H19: amount sesuai | I19: menmapilkan product
B20: TC03_001 | C20: Rounding Amount | D20: Positive | G20: 1 | H20: klik daily report | I20: Menampilkan sesuai category | K20: .
G21: 2 | H21: amount sesuai | I21: menmapilkan product
B22: TC03_001 | C22: Net sales | D22: Positive | G22: 1 | H22: klik daily report | I22: Menampilkan sesuai category | K22: .
G23: 2 | H23: amount sesuai | I23: menmapilkan product
B24: TC03_002 | C24: report by payment method | D24: Positive | G24: 1 | H24: klik Category | I24: Menampilkan sesuai category | K24: .
G25: 2 | H25: klik Subcategory | I25: menmapilkan product
G26: 3 | H26: klik product | I26: muncul pop up detail product
G27: 4 | H27: Add count product | I27: jumlah product bertambahberkurang
G28: 5 | H28: Add add ons | I28: Muncul button biru di add ons yang dipilih
G29: 6 | H29: Klik Add Order | I29: muncul detail pada sisi kanan tampilan
G30: 7 | H30: Klik Go To Payment | I30: Muncul bagian untuk memilih transaction
G31: 8 | H31: Pilih Payment method
G32: 9 | H32: Klik Proceed with payment
G33: 10 | H33: Klik Add Order
B34: TC03_002 | C34: report by promo pos | D34: Positive | F34: Order 1 product (food) | G34: 1 | H34: klik Category | I34: Menampilkan sesuai category | K34: .
F35: Order 2 product (food n drink) | G35: 2 | H35: klik Subcategory | I35: menmapilkan product
F36: Order kombinasi | G36: 3 | H36: klik product | I36: muncul pop up detail product
G37: 4 | H37: Add count product | I37: jumlah product bertambahberkurang
G38: 5 | H38: Add add ons | I38: Muncul button biru di add ons yang dipilih
G39: 6 | H39: Klik Add Order | I39: muncul detail pada sisi kanan tampilan
G40: 7 | H40: Klik Go To Payment | I40: Muncul bagian untuk memilih transaction
G41: 8 | H41: Pilih Payment method
...

Sheet Store_config
B2: =SUM(O3:O5)/O7 -> 0 | H2: Project | I2: =[1]Cover!B3 -> Project Name | N2: Summary | O2: =SUM(O3:O5)/O7 -> 0 | Q2: Detail:
H3: Test Scenario | I3: =[1]Cover!B11 -> TC01 Login | N3: Pass | O3: =COUNTIF(K7:K30,1) -> 0 | Q3: Total Positif Case | R3: =COUNTIF(D8:D17,"Positive") -> 2
B4: Percentage | H4: Date | I4: dd/mm/yyyy | N4: Failed | O4: =COUNTIF(K7:K30,0) -> 0 | Q4: Total Negative Case | R4: =COUNTIF(D9:D17,"Negative") -> 1
N5: Blocked | O5: =COUNTIF(K9:K32,"Block") -> 0
B6: TC ID | C6: Test Scenario | D6: Type | E6: Precondition | F6: Test Data | G6: Test Procedure | I6: Expected Result | J6: Actual Result | K6: Test Result | L6: Notes | N6: Not Yet Tested | O6: =COUNTIF(K7:K30,".") -> 3
B7: ot | N7: Total Case | O7: =SUM(O3:O6) -> 3
B8: TC01_001 | C8: Expired Token | D8: Positive | E8: Berada pada halaman login | F8: device | G8: 1 | H8: Input device token | I8: 1. Berhasil login | K8: .
G9: 2 | H9: Input PIN | I9: 2. Masuk ke halaman home
G10: 4 | H10: Klik tombol Login
B11: TC01_003 | C11: Reservation Notif before | D11: Positive | E11: Berada pada halaman login | G11: 1 | H11: Tekan Forgot Password | I11: Menampilkan input email | L11: apabila reservasi dari back office tidak ter apply confignya
G12: 2 | H12: Input e-mail | I12: Sesuai input
G13: 3 | H13: Input password baru | I13: Sesuai input
G14: 4 | H14: Login menggunakan password baru | I14: Login berhasil
B15: TC01_004 | C15: expired Reservation | D15: Negative | E15: Berada pada halaman login | G15: 1 | H15: Input username | I15: 1. Gagal login | L15: apabila reservasi dari back office tidak ter apply confignya
G16: 2 | H16: Input password | I16: 2. Muncul warning : Please input username and password
G17: 3 | H17: Klik tombol Login
B18: TC01_005 | C18: Maximum Vouchers | D18: Negative | E18: Berada pada halaman login | G18: 1 | H18: Input username | I18: 1. Gagal login
G19: 2 | H19: Input password | I19: 2. Muncul warning : Please input username and password
G20: 3 | H20: Klik tombol Login
B21: TC01_005 | C21: Reservation Feature | D21: Negative | E21: Berada pada halaman login | G21: 1 | H21: Input username | I21: 1. Gagal login | L21: belum bisa di handle
G22: 2 | H22: Input password | I22: 2. Muncul warning : Please input username and password
G23: 3 | H23: Klik tombol Login
B24: TC01_006 | C24: Validate Shift Log | D24: Negative | E24: Berada pada halaman login | G24: 1 | H24: Change password | I24: Password berhasil diubah | K24: .
G25: 2 | H25: Logout from application | I25: Logout berhasil
G26: 3 | H26: Login with old password | I26: Login gagal
B27: TC01_007 | C27: ROunding Type | D27: Negative | E27: Berada pada halaman login | G27: 1 | H27: Delete user | I27: Data berhasil dihapus | K27: .
G28: 2 | H28: Logout from application | I28: Logout berhasil
G29: 3 | H29: Login with deleted user | I29: Login gagal
B30: 1

Sheet Multiscreen
B2: =SUM(O3:O5)/O7 -> 0 | H2: Project | I2: =[1]Cover!B3 -> Project Name | N2: Summary | O2: =SUM(O3:O5)/O7 -> 0 | Q2: Detail:
H3: Test Scenario | I3: =[1]Cover!B11 -> TC01 Login | N3: Pass | O3: =COUNTIF(K7:K40,1) -> 0 | Q3: Total Positif Case | R3: =COUNTIF(D8:D30,"Positive") -> 5
B4: Percentage | H4: Date | I4: dd/mm/yyyy | N4: Failed | O4: =COUNTIF(K7:K40,0) -> 0 | Q4: Total Negative Case | R4: =COUNTIF(D9:D30,"Negative") -> 1
N5: Blocked | O5: =COUNTIF(K9:K42,"Block") -> 0
B6: TC ID | C6: Test Scenario | D6: Type | E6: Precondition | F6: Test Data | G6: Test Procedure | I6: Expected Result | J6: Actual Result | K6: Test Result | L6: Notes | N6: Not Yet Tested | O6: =COUNTIF(K7:K40,".") -> 9
B7: ot | N7: Total Case | O7: =SUM(O3:O6) -> 9
B8: TC01_001 | C8: Multiscreen saat order summary | D8: Positive | E8: Berada pada halaman login | F8: device | G8: 1 | H8: Input device token | I8: 1. Berhasil login | K8: .
G9: 2 | H9: Input PIN | I9: 2. Masuk ke halaman home
G10: 4 | H10: Klik tombol Login
B11: TC01_003 | C11: multiscreen ketika payment succedd | D11: Positive | E11: Berada pada halaman login | G11: 1 | H11: Tekan Forgot Password | I11: Menampilkan input email | K11: .
G12: 2 | H12: Input e-mail | I12: Sesuai input
G13: 3 | H13: Input password baru | I13: Sesuai input
G14: 4 | H14: Login menggunakan password baru | I14: Login berhasil
B15: TC01_003 | C15: multiscreen cash | D15: Positive | E15: Berada pada halaman login | G15: 1 | H15: Tekan Forgot Password | I15: Menampilkan input email | K15: .
G16: 2 | H16: Input e-mail | I16: Sesuai input
G17: 3 | H17: Input password baru | I17: Sesuai input
G18: 4 | H18: Login menggunakan password baru | I18: Login berhasil
B19: TC01_003 | C19: multiscreen edc | D19: Positive | E19: Berada pada halaman login | G19: 1 | H19: Tekan Forgot Password | I19: Menampilkan input email | K19: .
G20: 2 | H20: Input e-mail | I20: Sesuai input
G21: 3 | H21: Input password baru | I21: Sesuai input
G22: 4 | H22: Login menggunakan password baru | I22: Login berhasil
B23: TC01_003 | C23: multiscreen QRIS | D23: Positive | E23: Berada pada halaman login | G23: 1 | H23: Tekan Forgot Password | I23: Menampilkan input email | K23: . | L23: ada detail logo yang seharusnya disesuaikan
G24: 2 | H24: Input e-mail | I24: Sesuai input
G25: 3 | H25: Input password baru | I25: Sesuai input
G26: 4 | H26: Login menggunakan password baru | I26: Login berhasil
B27: Negative case
B28: TC01_004 | C28: cancel order | D28: Negative | E28: Berada pada halaman login | F28: user name: littletalk1 | G28: 1 | H28: Input username | I28: 1. Gagal login | K28: .
F29: password : littletalk | G29: 2 | H29: Input password | I29: 2. Muncul warning : Please input username and password
G30: 3 | H30: Klik tombol Login
B31: TC01_005 | C31: edit payment | D31: Negative | E31: Berada pada halaman login | F31: user name: userbaru | G31: 1 | H31: Input username | I31: 1. Gagal login | K31: . | L31: apabila dilakukan edit tidak berubah
G32: 2 | H32: Input password | I32: 2. Muncul warning : Please input username and password
G33: 3 | H33: Klik tombol Login
B34: TC01_005 | C34: QRIS timeout | D34: Negative | E34: Berada pada halaman login | F34: user name: userbaru | G34: 1 | H34: Input username | I34: 1. Gagal login | K34: .
G35: 2 | H35: Input password | I35: 2. Muncul warning : Please input username and password
G36: 3 | H36: Klik tombol Login
B37: TC01_005 | C37: mengganti payment method | D37: Negative | E37: Berada pada halaman login | F37: user name: userbaru | G37: 1 | H37: Input username | I37: 1. Gagal login | K37: .
G38: 2 | H38: Input password | I38: 2. Muncul warning : Please input username and password
G39: 3 | H39: Klik tombol Login
B40: 1

Sheet scanner
B2: =SUM(O3:O5)/O7 -> 0 | H2: Project | I2: =[1]Cover!B3 -> Project Name | N2: Summary | O2: =SUM(O3:O5)/O7 -> 0 | Q2: Detail:
H3: Test Scenario | I3: =[1]Cover!B11 -> TC01 Login | N3: Pass | O3: =COUNTIF(K7:K42,1) -> 0 | Q3: Total Positif Case | R3: =COUNTIF(D8:D38,"Positive") -> 7
B4: Percentage | H4: Date | I4: dd/mm/yyyy | N4: Failed | O4: =COUNTIF(K7:K42,0) -> 0 | Q4: Total Negative Case | R4: =COUNTIF(D9:D38,"Negative") -> 1
N5: Blocked | O5: =COUNTIF(K9:K44,"Block") -> 0
B6: TC ID | C6: Test Scenario | D6: Type | E6: Precondition | F6: Test Data | G6: Test Procedure | I6: Expected Result | J6: Actual Result | K6: Test Result | L6: Notes | N6: Not Yet Tested | O6: =COUNTIF(K7:K42,".") -> 9
B7: ot | N7: Total Case | O7: =SUM(O3:O6) -> 9
B8: TC01_001 | C8: scan barcode | D8: Positive | E8: Berada pada halaman login | F8: device | G8: 1 | H8: Input device token | I8: 1. Berhasil login | K8: .
G9: 2 | H9: Input PIN | I9: 2. Masuk ke halaman home
G10: 4 | H10: Klik tombol Login
B11: TC01_003 | C11: scan QR | D11: Positive | E11: Berada pada halaman login | G11: 1 | H11: Tekan Forgot Password | I11: Menampilkan input email | K11: .
G12: 2 | H12: Input e-mail | I12: Sesuai input
G13: 3 | H13: Input password baru | I13: Sesuai input
G14: 4 | H14: Login menggunakan password baru | I14: Login berhasil
B15: TC01_003 | C15: Scan barcode sku lebih dari 2 | D15: Positive | E15: Berada pada halaman login | G15: 1 | H15: Tekan Forgot Password | I15: Menampilkan input email | K15: .
G16: 2 | H16: Input e-mail | I16: Sesuai input
G17: 3 | H17: Input password baru | I17: Sesuai input
G18: 4 | H18: Login menggunakan password baru | I18: Login berhasil
B19: TC01_003 | C19: scan QR lebih dari 2 | D19: Positive | E19: Berada pada halaman login | G19: 1 | H19: Tekan Forgot Password | I19: Menampilkan input email | K19: .
G20: 2 | H20: Input e-mail | I20: Sesuai input
G21: 3 | H21: Input password baru | I21: Sesuai input
G22: 4 | H22: Login menggunakan password baru | I22: Login berhasil
B23: TC01_003 | C23: scan barcode not spesific | D23: Positive | E23: Berada pada halaman login | G23: 1 | H23: Tekan Forgot Password | I23: Menampilkan input email | K23: .
G24: 2 | H24: Input e-mail | I24: Sesuai input
G25: 3 | H25: Input password baru | I25: Sesuai input
G26: 4 | H26: Login menggunakan password baru | I26: Login berhasil
B27: TC01_003 | C27: scan QR not spesific | D27: Positive | E27: Berada pada halaman login | G27: 1 | H27: Tekan Forgot Password | I27: Menampilkan input email | K27: .
G28: 2 | H28: Input e-mail | I28: Sesuai input
G29: 3 | H29: Input password baru | I29: Sesuai input
G30: 4 | H30: Login menggunakan password baru | I30: Login berhasil
B31: TC01_003 | C31: scan qr spasi | D31: Positive | E31: Berada pada halaman login | G31: 1 | H31: Tekan Forgot Password | I31: Menampilkan input email | K31: .
G32: 2 | H32: Input e-mail | I32: Sesuai input
G33: 3 | H33: Input password baru | I33: Sesuai input
G34: 4 | H34: Login menggunakan password baru | I34: Login berhasil
B35: Negative case
B36: TC01_004 | C36: cancel order | D36: Negative | E36: Berada pada halaman login | F36: user name: littletalk1 | G36: 1 | H36: Input username | I36: 1. Gagal login | K36: .
F37: password : littletalk | G37: 2 | H37: Input password | I37: 2. Muncul warning : Please input username and password
G38: 3 | H38: Klik tombol Login
B39: TC01_005 | C39: mengganti payment method | D39: Negative | E39: Berada pada halaman login | F39: user name: userbaru | G39: 1 | H39: Input username | I39: 1. Gagal login | K39: .
G40: 2 | H40: Input password | I40: 2. Muncul warning : Please input username and password
G41: 3 | H41: Klik tombol Login
...

Sheet printer
B2: =SUM(O3:O4)/SUM(O6:O6) -> 0 | H2: Project | L2: Pass [.] | N2: Summary | O2: =SUM(O3:O5)/O7 -> 0 | Q2: Detail:
H3: Test Scenario | L3: Fail [0] | N3: Pass | O3: =COUNTIF(K7:K86,1) -> 0 | Q3: Total Positif Case | R3: =COUNTIF(D8:D85,"Positive") -> 8
B4: Percentage | H4: Date | L4: Not yet tested [blank] | N4: Failed | O4: =COUNTIF(K7:K86,0) -> 0 | Q4: Total Negative Case | R4: =COUNTIF(D15:D85,"Negative") -> 0
N5: Blocked | O5: =COUNTIF(K15:K88,"Block") -> 0
B6: TC ID | C6: Test Scenario | D6: Type | E6: Precondition | F6: Test Data | G6: Test Procedure | I6: Expected Result | J6: Actual Result | K6: Test Result | L6: Comment | N6: Not Yet Tested | O6: =COUNTIF(K7:K86,".") -> 8
N7: Total Case | O7: =SUM(O3:O6) -> 8
B8: Case Sale On Us
B9: TC06_001 | C9: edit setting printer | D9: Positive | G9: 1 | H9: Tambah product di back office | I9: berhasil | K9: . | L9: tidak muncul
G10: 2 | H10: langsung refresh di menu product | I10: Menampilkan masking
G11: 3 | H11: product bertambah | I11: Menampilkan masking
B12: TC06_001 | C12: edit setting kategori ke banyak | D12: Positive | G12: 1 | H12: Tambah product di back office | I12: berhasil | K12: . | L12: tidak muncul
G13: 2 | H13: langsung refresh di menu product | I13: Menampilkan masking
G14: 3 | H14: product bertambah | I14: Menampilkan masking
B15: TC06_001 | C15: print ui kitchen | D15: Positive | G15: 1 | H15: Tambah product di back office | I15: berhasil | K15: . | L15: ketika pertama kali printer dihidupkan meskipun di refresh logo di tampilan tetap silang. perlu trigger transaksi/print duplicate baru logonya berubah jadi centang
G16: 2 | H16: langsung refresh di menu product | I16: Menampilkan masking
G17: 3
B18: TC06_002 | C18: printer cable kitchen | D18: Positive | G18: 1 | J18: Menampilkan informasi user | K18: .
G19: 2 | J19: Menampilkan sesuai input
G20: 3 | J20: Saat melakukan verifikasi email, nama tidak berubah
B21: TC06_004 | C21: printer cable bar | D21: Positive | G21: 1 | K21: .
G22: 2
G23: 3
B24: TC06_004 | C24: printer cable kasir | D24: Positive | G24: 1 | K24: .
G25: 2
G26: 3
B27: TC06_004 | C27: printer cable runner | D27: Positive | G27: 1 | K27: .
G28: 2
G29: 3
B30: TC06_004 | C30: printer cable checker | D30: Positive | G30: 1 | K30: .
G31: 2
G32: 3
B33: Negative Case

Sheet Sheet4
B4: Merchant | C4: Littletalk
B5: Store | C5: Littletalk Urban Forest
B6: Sales Mode | C6: online, takeaway, dine in
B7: Table | C7: Table 1, 2
B8: product category | C8: food
C9: beverages
B10: sub product category | C10: food | D10: appetizer
D11: main course
D12: dessert
C13: beverages | D13: coffee
D14: non cofee
B15: product | C15: product category | D15: sub product | E15: product | F15: variant | G15: product option
C16: food | D16: appetizer | E16: salad | F16: caesar salad | G16: extra cheese (optional)
F17: green salad | G17: hot ( mandatory)
F18: greek salad
C19: food | D19: appetizer | E19: pizza | F19: beef pizza | G19: hot (mandatory)
G20: extra beef (optional)
D21: appetizer | E21: wings bucket | F21: buldak wings bucket | G21: hot (mandatory)
F22: honey mustard wings bucket
D23: main course | E23: Fried rice | F23: chicken fried rice
F24: beef fried rice
D25: main course | E25: pasta | F25: bolongness

Sheet Revision History
B1: REVISION HISTORY
B3: Date | C3: Version | D3: Description
